{
 "cells": [
  {
   "cell_type": "code",
   "execution_count": 36,
   "id": "ed030458-c30d-4f2b-be0d-2a8aac762f74",
   "metadata": {},
   "outputs": [],
   "source": [
    "from keras.utils import normalize\n",
    "import os\n",
    "import cv2\n",
    "from PIL import Image\n",
    "import numpy as np\n",
    "from matplotlib import pyplot as plt\n",
    "from skimage import measure, color, io\n",
    "import tensorflow as tf\n",
    "from keras.models import model_from_json\n"
   ]
  },
  {
   "cell_type": "code",
   "execution_count": 37,
   "id": "38c19174-9530-4b12-9e64-b0d47a88c241",
   "metadata": {},
   "outputs": [],
   "source": [
    "# Load the JSON architecture file\n",
    "with open('D:/Rooftop-Solar-Energy-Potential-Map/ML/models/model_architecture_resnet.json', 'r') as f:\n",
    "    model_json = f.read()\n",
    "\n",
    "# Create the model from the JSON architecture\n",
    "model = model_from_json(model_json)\n"
   ]
  },
  {
   "cell_type": "code",
   "execution_count": 38,
   "id": "1aeb55a7-4e57-4ef1-8974-c0db2330022c",
   "metadata": {},
   "outputs": [],
   "source": [
    "model.load_weights('D:/Rooftop-Solar-Energy-Potential-Map/ML/models/model_weights_resnet.h5')"
   ]
  },
  {
   "cell_type": "code",
   "execution_count": 39,
   "id": "0b1c9210-4bd5-4c8f-9b4d-90744b236034",
   "metadata": {},
   "outputs": [
    {
     "name": "stdout",
     "output_type": "stream",
     "text": [
      "(1024, 1024, 3)\n"
     ]
    }
   ],
   "source": [
    "test_img = cv2.imread('D:\\Rooftop-Solar-Energy-Potential-Map\\ML\\data\\external\\source\\DL52_b53_4_9.tif',cv2.IMREAD_COLOR)\n",
    "print(test_img.shape)\n",
    "test_img = cv2.resize(test_img, (256,256))\n",
    "test_img_norm = np.expand_dims(normalize(np.array(test_img), axis=1),2)\n",
    "test_img_norm=test_img_norm[:,:,0][:,:,None]\n",
    "test_img_input=np.expand_dims(test_img_norm, 0)"
   ]
  },
  {
   "cell_type": "code",
   "execution_count": 40,
   "id": "26c32105-1fba-4962-ace1-94c3dcbd2ee9",
   "metadata": {},
   "outputs": [
    {
     "ename": "ValueError",
     "evalue": "in user code:\n\n    File \"C:\\Users\\vincetq\\.conda\\envs\\tf\\lib\\site-packages\\keras\\engine\\training.py\", line 2041, in predict_function  *\n        return step_function(self, iterator)\n    File \"C:\\Users\\vincetq\\.conda\\envs\\tf\\lib\\site-packages\\keras\\engine\\training.py\", line 2027, in step_function  **\n        outputs = model.distribute_strategy.run(run_step, args=(data,))\n    File \"C:\\Users\\vincetq\\.conda\\envs\\tf\\lib\\site-packages\\keras\\engine\\training.py\", line 2015, in run_step  **\n        outputs = model.predict_step(data)\n    File \"C:\\Users\\vincetq\\.conda\\envs\\tf\\lib\\site-packages\\keras\\engine\\training.py\", line 1983, in predict_step\n        return self(x, training=False)\n    File \"C:\\Users\\vincetq\\.conda\\envs\\tf\\lib\\site-packages\\keras\\utils\\traceback_utils.py\", line 70, in error_handler\n        raise e.with_traceback(filtered_tb) from None\n    File \"C:\\Users\\vincetq\\.conda\\envs\\tf\\lib\\site-packages\\keras\\engine\\input_spec.py\", line 295, in assert_input_compatibility\n        raise ValueError(\n\n    ValueError: Input 0 of layer \"ResNet50_U-Net\" is incompatible with the layer: expected shape=(None, 256, 256, 3), found shape=(None, 256, 256, 1, 3)\n",
     "output_type": "error",
     "traceback": [
      "\u001b[1;31m---------------------------------------------------------------------------\u001b[0m",
      "\u001b[1;31mValueError\u001b[0m                                Traceback (most recent call last)",
      "Cell \u001b[1;32mIn[40], line 1\u001b[0m\n\u001b[1;32m----> 1\u001b[0m segmented \u001b[38;5;241m=\u001b[39m (\u001b[43mmodel\u001b[49m\u001b[38;5;241;43m.\u001b[39;49m\u001b[43mpredict\u001b[49m\u001b[43m(\u001b[49m\u001b[43mtest_img_input\u001b[49m\u001b[43m)\u001b[49m[\u001b[38;5;241m0\u001b[39m,:,:,\u001b[38;5;241m0\u001b[39m] \u001b[38;5;241m>\u001b[39m \u001b[38;5;241m0.05\u001b[39m)\u001b[38;5;241m.\u001b[39mastype(np\u001b[38;5;241m.\u001b[39muint8)\n",
      "File \u001b[1;32m~\\.conda\\envs\\tf\\lib\\site-packages\\keras\\utils\\traceback_utils.py:70\u001b[0m, in \u001b[0;36mfilter_traceback.<locals>.error_handler\u001b[1;34m(*args, **kwargs)\u001b[0m\n\u001b[0;32m     67\u001b[0m     filtered_tb \u001b[38;5;241m=\u001b[39m _process_traceback_frames(e\u001b[38;5;241m.\u001b[39m__traceback__)\n\u001b[0;32m     68\u001b[0m     \u001b[38;5;66;03m# To get the full stack trace, call:\u001b[39;00m\n\u001b[0;32m     69\u001b[0m     \u001b[38;5;66;03m# `tf.debugging.disable_traceback_filtering()`\u001b[39;00m\n\u001b[1;32m---> 70\u001b[0m     \u001b[38;5;28;01mraise\u001b[39;00m e\u001b[38;5;241m.\u001b[39mwith_traceback(filtered_tb) \u001b[38;5;28;01mfrom\u001b[39;00m \u001b[38;5;28;01mNone\u001b[39;00m\n\u001b[0;32m     71\u001b[0m \u001b[38;5;28;01mfinally\u001b[39;00m:\n\u001b[0;32m     72\u001b[0m     \u001b[38;5;28;01mdel\u001b[39;00m filtered_tb\n",
      "File \u001b[1;32m~\\AppData\\Local\\Temp\\__autograph_generated_file7y3xmdqm.py:15\u001b[0m, in \u001b[0;36mouter_factory.<locals>.inner_factory.<locals>.tf__predict_function\u001b[1;34m(iterator)\u001b[0m\n\u001b[0;32m     13\u001b[0m \u001b[38;5;28;01mtry\u001b[39;00m:\n\u001b[0;32m     14\u001b[0m     do_return \u001b[38;5;241m=\u001b[39m \u001b[38;5;28;01mTrue\u001b[39;00m\n\u001b[1;32m---> 15\u001b[0m     retval_ \u001b[38;5;241m=\u001b[39m ag__\u001b[38;5;241m.\u001b[39mconverted_call(ag__\u001b[38;5;241m.\u001b[39mld(step_function), (ag__\u001b[38;5;241m.\u001b[39mld(\u001b[38;5;28mself\u001b[39m), ag__\u001b[38;5;241m.\u001b[39mld(iterator)), \u001b[38;5;28;01mNone\u001b[39;00m, fscope)\n\u001b[0;32m     16\u001b[0m \u001b[38;5;28;01mexcept\u001b[39;00m:\n\u001b[0;32m     17\u001b[0m     do_return \u001b[38;5;241m=\u001b[39m \u001b[38;5;28;01mFalse\u001b[39;00m\n",
      "\u001b[1;31mValueError\u001b[0m: in user code:\n\n    File \"C:\\Users\\vincetq\\.conda\\envs\\tf\\lib\\site-packages\\keras\\engine\\training.py\", line 2041, in predict_function  *\n        return step_function(self, iterator)\n    File \"C:\\Users\\vincetq\\.conda\\envs\\tf\\lib\\site-packages\\keras\\engine\\training.py\", line 2027, in step_function  **\n        outputs = model.distribute_strategy.run(run_step, args=(data,))\n    File \"C:\\Users\\vincetq\\.conda\\envs\\tf\\lib\\site-packages\\keras\\engine\\training.py\", line 2015, in run_step  **\n        outputs = model.predict_step(data)\n    File \"C:\\Users\\vincetq\\.conda\\envs\\tf\\lib\\site-packages\\keras\\engine\\training.py\", line 1983, in predict_step\n        return self(x, training=False)\n    File \"C:\\Users\\vincetq\\.conda\\envs\\tf\\lib\\site-packages\\keras\\utils\\traceback_utils.py\", line 70, in error_handler\n        raise e.with_traceback(filtered_tb) from None\n    File \"C:\\Users\\vincetq\\.conda\\envs\\tf\\lib\\site-packages\\keras\\engine\\input_spec.py\", line 295, in assert_input_compatibility\n        raise ValueError(\n\n    ValueError: Input 0 of layer \"ResNet50_U-Net\" is incompatible with the layer: expected shape=(None, 256, 256, 3), found shape=(None, 256, 256, 1, 3)\n"
     ]
    }
   ],
   "source": [
    "segmented = (model.predict(test_img_input)[0,:,:,0] > 0.05).astype(np.uint8)"
   ]
  }
 ],
 "metadata": {
  "kernelspec": {
   "display_name": "Python (GPU)",
   "language": "python",
   "name": "gpu_env"
  },
  "language_info": {
   "codemirror_mode": {
    "name": "ipython",
    "version": 3
   },
   "file_extension": ".py",
   "mimetype": "text/x-python",
   "name": "python",
   "nbconvert_exporter": "python",
   "pygments_lexer": "ipython3",
   "version": "3.9.19"
  }
 },
 "nbformat": 4,
 "nbformat_minor": 5
}
